UnicodeDecodeError: 'utf-8' codec can't decode byte 0xe3 in position 82: invalid continuation byte
Traceback:
File "C:\Users\coelh\Pessoal\TI\CURSOS\JordanaDeDados_LucianoGalvaoFilho\PipelineDeDados\.venv\Lib\site-packages\streamlit\runtime\scriptrunner\exec_code.py", line 88, in exec_func_with_error_handling
    result = func()
             ^^^^^^
File "C:\Users\coelh\Pessoal\TI\CURSOS\JordanaDeDados_LucianoGalvaoFilho\PipelineDeDados\.venv\Lib\site-packages\streamlit\runtime\scriptrunner\script_runner.py", line 590, in code_to_exec
    exec(code, module.__dict__)
File "C:\Users\coelh\Pessoal\TI\CURSOS\JordanaDeDados_LucianoGalvaoFilho\PipelineDeDados\app.py", line 38, in <module>
    main()
File "C:\Users\coelh\Pessoal\TI\CURSOS\JordanaDeDados_LucianoGalvaoFilho\PipelineDeDados\app.py", line 32, in main
    salvar_no_postgres(venda)
File "C:\Users\coelh\Pessoal\TI\CURSOS\JordanaDeDados_LucianoGalvaoFilho\PipelineDeDados\database.py", line 20, in salvar_no_postgres
    conn = psycopg2.connect(
           ^^^^^^^^^^^^^^^^^
File "C:\Users\coelh\Pessoal\TI\CURSOS\JordanaDeDados_LucianoGalvaoFilho\PipelineDeDados\.venv\Lib\site-packages\psycopg2\__init__.py", line 122, in connect
    conn = _connect(dsn, connection_factory=connection_factory, **kwasync)
           ^^^^^^^^^^^^^^^^^^^^^^^^^^^^^^^^^^^^^^^^^^^^^^^^^^^^^^^^^^^^^^^